<?xml version="1.0"?>
<robot name="hdt_7dof" xmlns:xacro="http://www.ros.org/wiki/xacro">

	<!-- default inertia -->
	<xacro:macro name="default_inertia">
		<inertia
		ixx="0.0005" ixy="0.0" ixz="0.0"
		iyy="0.0005" iyz="0.0"
		izz="0.0005"/>
	</xacro:macro>

	<xacro:macro name="hdt_7dof_right" params="parent x y z yaw prefix">
		<!-- materials -->
		<material name="${prefix}green">
			<color rgba="${53/255} ${94/255} ${59/255} 1.0"/>
		</material>

		<material name="${prefix}black">
			<color rgba="${0/255} ${0/255} ${0/255} 1.0"/>
		</material>

		<material name="${prefix}grey">
			<color rgba="${40/255} ${40/255} ${40/255} 1.0"/>
		</material>

		<!-- segment 1 -->
		<joint name="${prefix}joint1" type="revolute">
			<hdt id="1" kmin="100" kmax="200" inertia="0.1"/>
			<axis xyz="1 0 0"/>
			<limit effort="60.0" lower="-3.1416" upper="1.0472" velocity="2.0944"/>
			<origin xyz="${x} ${y} ${z}" rpy="0 0 ${yaw}"/>
			<parent link="${parent}"/>
			<child link="${prefix}link1"/>
			<dynamics damping="0.7" friction="0.0"/>
		</joint>

		<transmission name="${prefix}tran1">
			<type>transmission_interface/SimpleTransmission</type>
			<joint name="${prefix}joint1">
				<hardwareInterface>EffortJointInterface</hardwareInterface>
			</joint>
			<actuator name="${prefix}motor1">
				<mechanicalReduction>1</mechanicalReduction>
			</actuator>
		</transmission>

		<link name="${prefix}link1">
			<collision>
				<origin xyz="0 0 0" rpy="0 0 0"/>
				<geometry>
					<mesh filename="package://hdt_7dof_description/meshes/hdt_7dof_1_right.STL"/>
				</geometry>
			</collision>

			<visual>
				<origin xyz="0 0 0" rpy="0 0 0"/>
				<geometry>
					<mesh filename="package://hdt_7dof_description/meshes/hdt_7dof_1_right.STL"/>
				</geometry>
				<material name="${prefix}green"/>
			</visual>

			<inertial>
			<origin xyz="-0.04488 0 0" rpy="0 0 0"/>
			<mass value="1.00775"/>
				<inertia
				ixx="0.00064952" ixy="0.0" ixz="0.0"
				iyy="0.00104342" iyz="0.0"
				izz="0.00104342"/>
			</inertial>
		</link>
		<gazebo reference="${prefix}link1">
			<material>Gazebo/Green</material>
		</gazebo>

		<joint name="${prefix}joint1f" type="fixed">
			<parent link="${prefix}link1"/>
			<child link="${prefix}link2a"/>
			<origin xyz="-0.09217 0 0" rpy="0 0 0"/>
		</joint>

		<link name="${prefix}link2a">
			<collision>
				<origin xyz="0 0 0" rpy="0 0 0"/>
				<geometry>
					<mesh filename="package://hdt_7dof_description/meshes/hdt_7dof_2a_right.STL"/>
				</geometry>
			</collision>

			<visual>
				<origin xyz="0 0 0" rpy="0 0 0"/>
				<geometry>
					<mesh filename="package://hdt_7dof_description/meshes/hdt_7dof_2a_right.STL"/>
				</geometry>
				<material name="${prefix}black"/>
			</visual>

			<inertial>
				<origin xyz="-0.04416876 0 0" rpy="0 0 0"/>
				<mass value="0.66774822"/>
				<inertia
				ixx="0.00062987" ixy="0.0" ixz="0.0"
				iyy="0.00091291" iyz="0.0"
				izz="0.00110241"/>
			</inertial>
		</link>
		<gazebo reference="${prefix}link2a">
			<material>Gazebo/Black</material>
		</gazebo>

		<!-- segment 2 -->
		<joint name="${prefix}joint2" type="revolute">
			<hdt id="2" kmin="100" kmax="200" inertia="0.1"/>
			<axis xyz="0 -1 0"/>
			<limit effort="60.0" lower="-3.1416" upper="0.5236" velocity="2.0944"/>
			<origin xyz="-0.07 0 0" rpy="0 0 0"/>
			<parent link="${prefix}link2a"/>
			<child link="${prefix}link2b"/>
			<dynamics damping="0.7" friction="0.0"/>
		</joint>

		<transmission name="${prefix}tran2">
			<type>transmission_interface/SimpleTransmission</type>
			<joint name="${prefix}joint2">
				<hardwareInterface>EffortJointInterface</hardwareInterface>
			</joint>
			<actuator name="${prefix}motor2">
				<mechanicalReduction>1</mechanicalReduction>
			</actuator>
		</transmission>

		<link name="${prefix}link2b">
			<collision>
				<origin xyz="0 0 0" rpy="0 0 0"/>
				<geometry>
					<mesh filename="package://hdt_7dof_description/meshes/hdt_7dof_2b.STL"/>
				</geometry>
			</collision>

			<visual>
				<origin xyz="0 0 0.0" rpy="0 0 0"/>
				<geometry>
					<mesh filename="package://hdt_7dof_description/meshes/hdt_7dof_2b.STL"/>
				</geometry>
				<material name="${prefix}grey"/>
			</visual>

			<inertial>
				<origin xyz="0 0 -0.02018105" rpy="0 0 0"/>
				<mass value="0.69896"/>
				<inertia
				ixx="0.00088116" ixy="0.0" ixz="0.0"
				iyy="0.00094182" iyz="0.0"
				izz="0.00032992"/>
			</inertial>
		</link>
		<gazebo reference="${prefix}link2b">
			<material>Gazebo/Grey</material>
		</gazebo>

		<!-- segment 3 -->
		<joint name="${prefix}joint3" type="revolute">
			<hdt id="3" kmin="75" kmax="150" inertia="0.075"/>
			<axis xyz="0 0 1"/>
			<limit effort="60.0" lower="-2.0944" upper="2.0944" velocity="2.0944"/>
			<origin xyz="0 0 -0.077" rpy="0 0 0" />
			<parent link="${prefix}link2b"/>
			<child link="${prefix}link3"/>
			<dynamics damping="0.7" friction="0.0"/>
		</joint>

		<transmission name="${prefix}tran3">
			<type>transmission_interface/SimpleTransmission</type>
			<joint name="${prefix}joint3">
				<hardwareInterface>EffortJointInterface</hardwareInterface>
			</joint>
			<actuator name="${prefix}motor3">
				<mechanicalReduction>1</mechanicalReduction>
			</actuator>
		</transmission>

		<link name="${prefix}link3">
			<collision>
				<origin xyz="0 0 0.0" rpy="0 0 0"/>
				<geometry>
					<mesh filename="package://hdt_7dof_description/meshes/hdt_7dof_3.STL"/>
				</geometry>
			</collision>

			<visual>
				<origin xyz="0 0 0.0" rpy="0 0 0"/>
				<geometry>
					<mesh filename="package://hdt_7dof_description/meshes/hdt_7dof_3.STL"/>
				</geometry>
				<material name="${prefix}green"/>
			</visual>

			<inertial>
				<origin xyz="0 0 -0.08013953" rpy="0 0 0"/>
				<mass value="1.77733729"/>
				<inertia
				ixx="0.00450640" ixy="0.0" ixz="0.0"
				iyy="0.00450640" iyz="0.0"
				izz="0.00114447"/>
			</inertial>
		</link>
		<gazebo reference="${prefix}link3">
			<material>Gazebo/Green</material>
		</gazebo>

		<joint name="${prefix}joint3f" type="fixed">
			<origin xyz="0 0 -0.16271" rpy="0 0 0"/>
			<parent link="${prefix}link3"/>
			<child link="${prefix}link4a"/>
		</joint>

		<link name="${prefix}link4a">
			<collision>
				<origin xyz="0 0 0" rpy="0 0 0"/>
				<geometry>
					<mesh filename="package://hdt_7dof_description/meshes/hdt_7dof_4a.STL"/>
				</geometry>
			</collision>

			<visual>
				<origin xyz="0 0 0.0" rpy="0 0 0"/>
				<geometry>
					<mesh filename="package://hdt_7dof_description/meshes/hdt_7dof_4a.STL"/>
				</geometry>
				<material name="${prefix}black"/>
			</visual>

			<inertial>
				<origin xyz="0 0 -0.04416876" rpy="0 0 0"/>
				<mass value="0.66774822"/>
				<inertia
				ixx="0.00091291" ixy="0.0" ixz="0.0"
				iyy="0.00110241" iyz="0.0"
				izz="0.00062987"/>
			</inertial>
		</link>
		<gazebo reference="${prefix}link4a">
			<material>Gazebo/Black</material>
		</gazebo>

		<!-- segment 4 -->
		<joint name="${prefix}joint4" type="revolute">
			<hdt id="4" kmin="75" kmax="150" inertia="0.075"/>
			<axis xyz="1 0 0"/>
			<limit effort="60.0" lower="-0.5236" upper="3.6652" velocity="2.0944"/>
			<origin xyz="0 0 -0.07" rpy="0 0 0"/>
			<parent link="${prefix}link4a"/>
			<child link="${prefix}link4b"/>
			<dynamics damping="0.7" friction="0.0"/>
		</joint>

		<transmission name="${prefix}tran4">
			<type>transmission_interface/SimpleTransmission</type>
			<joint name="${prefix}joint4">
				<hardwareInterface>EffortJointInterface</hardwareInterface>
			</joint>
			<actuator name="${prefix}motor4">
				<mechanicalReduction>1</mechanicalReduction>
			</actuator>
		</transmission>

		<link name="${prefix}link4b">
			<collision>
				<origin xyz="0 0 0" rpy="0 0 0"/>
				<geometry>
					<mesh filename="package://hdt_7dof_description/meshes/hdt_7dof_4b.STL"/>
				</geometry>
			</collision>

			<visual>
				<origin xyz="0 0 0.0" rpy="0 0 0"/>
				<geometry>
					<mesh filename="package://hdt_7dof_description/meshes/hdt_7dof_4b.STL"/>
				</geometry>
				<material name="${prefix}grey"/>
			</visual>

			<inertial>
				<origin xyz="0 -0.02018105 0" rpy="0 0 0"/>
				<mass value="0.69896279"/>
				<inertia
				ixx="0.00094182" ixy="0.0" ixz="0.0"
				iyy="0.00032992" iyz="0.0"
				izz="0.00088116"/>
			</inertial>
		</link>
		<gazebo reference="${prefix}link4b">
			<material>Gazebo/Grey</material>
		</gazebo>

		<!-- segment 5 -->
		<joint name="${prefix}joint5" type="revolute">
			<hdt id="5" kmin="50" kmax="100" inertia="0.05"/>
			<axis xyz="0 -1 0"/>
			<limit effort="60.0" lower="-2.0944" upper="2.0944" velocity="2.0944"/>
			<origin xyz="0 -0.077 0" rpy="0 0 0"/>
			<parent link="${prefix}link4b"/>
			<child link="${prefix}link5"/>
			<dynamics damping="0.7" friction="0.0"/>
		</joint>

		<transmission name="${prefix}tran5">
			<type>transmission_interface/SimpleTransmission</type>
			<joint name="${prefix}joint5">
				<hardwareInterface>EffortJointInterface</hardwareInterface>
			</joint>
			<actuator name="${prefix}motor5">
				<mechanicalReduction>1</mechanicalReduction>
			</actuator>
		</transmission>

		<link name="${prefix}link5">
			<collision>
				<origin xyz="0 0 0.0" rpy="0 0 0"/>
				<geometry>
					<mesh filename="package://hdt_7dof_description/meshes/hdt_7dof_5.STL"/>
				</geometry>
			</collision>

			<visual>
				<origin xyz="0 0 0.0" rpy="0 0 0"/>
				<geometry>
					<mesh filename="package://hdt_7dof_description/meshes/hdt_7dof_5.STL"/>
				</geometry>
				<material name="${prefix}green"/>
			</visual>

			<inertial>
				<origin xyz="0 -0.04487724 0" rpy="0 0 0"/>
				<mass value="1.00775488"/>
				<inertia
				ixx="0.00104342" ixy="0.0" ixz="0.0"
				iyy="0.00064952" iyz="0.0"
				izz="0.00104342"/>
			</inertial>
		</link>
		<gazebo reference="${prefix}link5">
			<material>Gazebo/Green</material>
		</gazebo>

		<joint name="${prefix}joint5f" type="fixed">
			<origin xyz="0 -0.09217 0" rpy="0 0 0"/>
			<parent link="${prefix}link5"/>
			<child link="${prefix}link6a"/>
		</joint>

		<link name="${prefix}link6a">
			<collision>
				<origin xyz="0 0 0" rpy="0 0 0"/>
				<geometry>
					<mesh filename="package://hdt_7dof_description/meshes/hdt_7dof_6a.STL"/>
				</geometry>
			</collision>

			<visual>
				<origin xyz="0 0 0.0" rpy="0 0 0"/>
				<geometry>
					<mesh filename="package://hdt_7dof_description/meshes/hdt_7dof_6a.STL"/>
				</geometry>
				<material name="${prefix}black"/>
			</visual>

			<inertial>
				<origin xyz="0 -0.04112 0" rpy="0 0 0"/>
				<mass value="0.50058"/>
				<inertia
				ixx="0.000580228" ixy="0.0" ixz="0.0"
				iyy="0.000541503" iyz="0.0"
				izz="0.000750977"/>
			</inertial>
		</link>
		<gazebo reference="${prefix}link6a">
			<material>Gazebo/Black</material>
		</gazebo>

		<!-- segment 6 -->
		<joint name="${prefix}joint6" type="revolute">
			<hdt id="6" kmin="50" kmax="100" inertia="0.05"/>
			<axis xyz="1 0 0"/>
			<limit effort="60.0" lower="-1.5708" upper="1.5708" velocity="2.0944"/>
			<origin xyz="0 -0.055 0" rpy="0 0 0"/>
			<parent link="${prefix}link6a"/>
			<child link="${prefix}link6b"/>
			<dynamics damping="0.7" friction="0.0"/>
		</joint>

		<transmission name="${prefix}tran6">
			<type>transmission_interface/SimpleTransmission</type>
			<joint name="${prefix}joint6">
				<hardwareInterface>EffortJointInterface</hardwareInterface>
			</joint>
			<actuator name="${prefix}motor6">
				<mechanicalReduction>1</mechanicalReduction>
			</actuator>
		</transmission>

		<link name="${prefix}link6b">
			<collision>
				<origin xyz="0 0 0" rpy="0 0 0"/>
				<geometry>
					<mesh filename="package://hdt_7dof_description/meshes/hdt_7dof_6b.STL"/>
				</geometry>
			</collision>

			<visual>
				<origin xyz="0 0 0.0" rpy="0 0 0"/>
				<geometry>
					<mesh filename="package://hdt_7dof_description/meshes/hdt_7dof_6b.STL"/>
				</geometry>
				<material name="${prefix}grey"/>
			</visual>

			<inertial>
				<origin xyz="0 -0.03855 0" rpy="0 0 0"/>
				<mass value="0.99934"/>
				<inertia
				ixx="0.001905243" ixy="0.0" ixz="0.0"
				iyy="0.000474765" iyz="0.0"
				izz="0.001905243"/>
			</inertial>
		</link>
		<gazebo reference="${prefix}link6b">
			<material>Gazebo/Grey</material>
		</gazebo>

		<!-- segment 7 -->
		<joint name="${prefix}joint7" type="revolute">
			<hdt id="7" kmin="50" kmax="100" inertia="0.05"/>
			<axis xyz="0 0 1"/>
			<limit effort="60.0" lower="-1.5708" upper="1.5708" velocity="2.0944"/>
			<origin xyz="0 -0.0771 0" rpy="0 0 0"/>
			<parent link="${prefix}link6b"/>
			<child link="${prefix}link7"/>
			<dynamics damping="0.7" friction="0.0"/>
		</joint>

		<transmission name="${prefix}tran7">
			<type>transmission_interface/SimpleTransmission</type>
			<joint name="${prefix}joint7">
				<hardwareInterface>EffortJointInterface</hardwareInterface>
			</joint>
			<actuator name="${prefix}motor7">
				<mechanicalReduction>1</mechanicalReduction>
			</actuator>
		</transmission>

		<link name="${prefix}link7">
			<collision>
				<origin xyz="0 0 0" rpy="0 0 0"/>
				<geometry>
					<mesh filename="package://hdt_7dof_description/meshes/hdt_7dof_7.STL"/>
				</geometry>
			</collision>

			<visual>
				<origin xyz="0 0 0.0" rpy="0 0 0"/>
				<geometry>
					<mesh filename="package://hdt_7dof_description/meshes/hdt_7dof_7.STL"/>
				</geometry>
				<material name="${prefix}black"/>
			</visual>

			<inertial>
				<origin xyz="0 -0.01177 0" rpy="0 0 0"/>
				<mass value="0.47608"/>
				<inertia
				ixx="0.000705091" ixy="0.0" ixz="0.0"
				iyy="0.000537081" iyz="0.0"
				izz="0.000534342"/>
			</inertial>
		</link>
		<gazebo reference="${prefix}link7">
			<material>Gazebo/Black</material>
		</gazebo>

		<!-- palm -->
		<joint name="${prefix}palm" type="fixed">
			<origin xyz="0 -0.055 0" rpy="0 0 0"/>
			<parent link="${prefix}link7"/>
			<child link="${prefix}palm"/>
		</joint>

		<link name="${prefix}palm">
			<collision>
				<origin xyz="0 0 0" rpy="0 0 0"/>
				<geometry>
					<mesh filename="package://hdt_7dof_description/meshes/hdt_7dof_palm.STL"/>
				</geometry>
			</collision>

			<visual>
				<origin xyz="0 0 0.0" rpy="0 0 0"/>
				<geometry>
					<mesh filename="package://hdt_7dof_description/meshes/hdt_7dof_palm.STL"/>
				</geometry>
				<material name="${prefix}black"/>
			</visual>

			<inertial>
				<origin xyz="0 -0.08326 -0.00539" rpy="0 0 0"/>
				<mass value="0.56756"/>
				<inertia
				ixx="0.001727803" ixy="0.000001205" ixz="0.0"
				iyy="0.000549457" iyz="-0.000101997"
				izz="0.001418031"/>
			</inertial>
		</link>
		<gazebo reference="${prefix}palm">
			<material>Gazebo/Black</material>
		</gazebo>

		<!-- thumb base -->
		<joint name="${prefix}thumb_base" type="revolute">
			<hdt id="10" kmin="5" kmax="20" inertia="0.01"/>
			<axis xyz="0 -1 0"/>
			<limit effort="4.0" lower="-1.5708" upper="1.5708" velocity="4.1888"/>
			<origin xyz="0 -0.05039 0.01529" rpy="0 0 0"/>
			<parent link="${prefix}palm"/>
			<child link="${prefix}thumb_base"/>
			<dynamics damping="0.7" friction="0.0"/>
		</joint>

		<transmission name="${prefix}tran10">
			<type>transmission_interface/SimpleTransmission</type>
			<joint name="${prefix}thumb_base">
				<hardwareInterface>EffortJointInterface</hardwareInterface>
			</joint>
			<actuator name="${prefix}motor10">
				<mechanicalReduction>1</mechanicalReduction>
			</actuator>
		</transmission>

		<link name="${prefix}thumb_base">
			<collision>
				<origin xyz="0 0 0" rpy="0 0 0"/>
				<geometry>
					<mesh filename="package://hdt_7dof_description/meshes/hdt_7dof_thumb_base.STL"/>
				</geometry>
			</collision>

			<visual>
				<origin xyz="0 0 0" rpy="0 0 0"/>
				<geometry>
					<mesh filename="package://hdt_7dof_description/meshes/hdt_7dof_thumb_base.STL"/>
				</geometry>
				<material name="${prefix}grey"/>
			</visual>

			<inertial>
				<origin xyz="0 -0.02653 0.02207" rpy="0 0 0"/>
				<mass value="0.08562"/>
				<inertia
				ixx="0.0000315" ixy="0.0" ixz="0.0"
				iyy="0.000034299" iyz="0.0"
				izz="0.000022344"/>
			</inertial>
		</link>
		<gazebo reference="${prefix}thumb_base">
			<material>Gazebo/Grey</material>
		</gazebo>

		<!-- thumb prox -->
		<joint name="${prefix}thumb_prox" type="revolute">
			<hdt id="11" kmin="5" kmax="20" inertia="0.01"/>
			<axis xyz="1 0 0"/>
			<limit effort="4.0" lower="-0.7854" upper="1.5708" velocity="4.1888"/>
			<origin xyz="0.00214 -0.02759 0.05700" rpy="0 0 0"/>
			<parent link="${prefix}thumb_base"/>
			<child link="${prefix}thumb_prox"/>
			<dynamics damping="0.7" friction="0.0"/>
		</joint>

		<transmission name="${prefix}tran11">
			<type>transmission_interface/SimpleTransmission</type>
			<joint name="${prefix}thumb_prox">
				<hardwareInterface>EffortJointInterface</hardwareInterface>
			</joint>
			<actuator name="${prefix}motor11">
				<mechanicalReduction>1</mechanicalReduction>
			</actuator>
		</transmission>

		<link name="${prefix}thumb_prox">
			<collision>
				<origin xyz="0 0 0" rpy="0 0 0"/>
				<geometry>
					<mesh filename="package://hdt_7dof_description/meshes/hdt_7dof_thumb_prox.STL"/>
				</geometry>
			</collision>

			<visual>
				<origin xyz="0 0 0" rpy="0 0 0"/>
				<geometry>
					<mesh filename="package://hdt_7dof_description/meshes/hdt_7dof_thumb_prox.STL"/>
				</geometry>
				<material name="${prefix}grey"/>
			</visual>

			<inertial>
				<origin xyz="0 0.001 0.02063" rpy="0 0 0"/>
				<mass value="0.02523"/>
				<xacro:default_inertia />
				<!-- <inertia
				ixx="0.000004718" ixy="0.0" ixz="0.0"
				iyy="0.000005374" iyz="-0.000000071"
				izz="0.000002921"/> -->
			</inertial>
		</link>
		<gazebo reference="${prefix}thumb_prox">
			<material>Gazebo/Grey</material>
		</gazebo>

		<!-- thumb med -->
		<joint name="${prefix}thumb_med" type="fixed">
			<origin xyz="0 0.00285 0.04341" rpy="0 0 0"/>
			<parent link="${prefix}thumb_prox"/>
			<child link="${prefix}thumb_med"/>
		</joint>

		<link name="${prefix}thumb_med">
			<collision>
				<origin xyz="0 0 0" rpy="0 0 0"/>
				<geometry>
					<mesh filename="package://hdt_7dof_description/meshes/hdt_7dof_thumb_med.STL"/>
				</geometry>
			</collision>

			<visual>
				<origin xyz="0 0 0" rpy="0 0 0"/>
				<geometry>
					<mesh filename="package://hdt_7dof_description/meshes/hdt_7dof_thumb_med.STL"/>
				</geometry>
				<material name="${prefix}black"/>
			</visual>

			<inertial>
				<origin xyz="0 -0.00353 0.01162" rpy="0 0 0"/>
				<mass value="0.0085"/>
				<inertia
				ixx="0.000001099" ixy="0.0" ixz="0.0"
				iyy="0.000001639" iyz="0.000000096"
				izz="0.000000981"/>
			</inertial>
		</link>
		<gazebo reference="${prefix}thumb_med">
			<material>Gazebo/Black</material>
		</gazebo>

		<!-- thumb dist -->
		<joint name="${prefix}thumb_dist" type="fixed">
			<origin xyz="0 -0.0009 0.02769" rpy="0 0 0"/>
			<parent link="${prefix}thumb_med"/>
			<child link="${prefix}thumb_dist"/>
		</joint>

		<link name="${prefix}thumb_dist">
			<collision>
				<origin xyz="0 0 0" rpy="0 0 0"/>
				<geometry>
					<mesh filename="package://hdt_7dof_description/meshes/hdt_7dof_thumb_dist.STL"/>
				</geometry>
			</collision>

			<visual>
				<origin xyz="0 0 0" rpy="0 0 0"/>
				<geometry>
					<mesh filename="package://hdt_7dof_description/meshes/hdt_7dof_thumb_dist.STL"/>
				</geometry>
				<material name="${prefix}grey"/>
			</visual>

			<inertial>
				<origin xyz="0 -0.00131 0.01323" rpy="0 0 0"/>
				<mass value="0.0092"/>
				<inertia
				ixx="0.00000066" ixy="0.0" ixz="0.0"
				iyy="0.000000837" iyz="0.0"
				izz="0.000000695"/>
			</inertial>
		</link>
		<gazebo reference="${prefix}thumb_dist">
			<material>Gazebo/Grey</material>
		</gazebo>

		<!-- index prox -->
		<joint name="${prefix}index_prox" type="revolute">
			<hdt id="12" kmin="5" kmax="20" inertia="0.01"/>
			<axis xyz="0 0 1"/>
			<limit effort="4.0" lower="-0.7854" upper="1.5708" velocity="4.1888"/>
			<origin xyz="0 -0.16325 0.02701" rpy="0 0 0"/>
			<parent link="${prefix}palm"/>
			<child link="${prefix}index_prox"/>
			<dynamics damping="0.7" friction="0.0"/>
		</joint>

		<transmission name="${prefix}tran12">
			<type>transmission_interface/SimpleTransmission</type>
			<joint name="${prefix}index_prox">
				<hardwareInterface>EffortJointInterface</hardwareInterface>
			</joint>
			<actuator name="${prefix}motor12">
				<mechanicalReduction>1</mechanicalReduction>
			</actuator>
		</transmission>

		<link name="${prefix}index_prox">
			<collision>
				<origin xyz="0 0 0" rpy="0 0 0"/>
				<geometry>
					<mesh filename="package://hdt_7dof_description/meshes/hdt_7dof_index_prox_right.STL"/>
				</geometry>
			</collision>

			<visual>
				<origin xyz="0 0 0" rpy="0 0 0"/>
				<geometry>
					<mesh filename="package://hdt_7dof_description/meshes/hdt_7dof_index_prox_right.STL"/>
				</geometry>
				<material name="${prefix}grey"/>
			</visual>

			<inertial>
				<origin xyz="-0.001 -0.02063 0" rpy="0 0 0"/>
				<mass value="0.02523"/>
				<xacro:default_inertia />
				<!-- <inertia
				ixx="0.000005374" ixy="-0.000000071" ixz="0.0"
				iyy="0.000002921" iyz="0.0"
				izz="0.000004718"/> -->
			</inertial>
		</link>
		<gazebo reference="${prefix}index_prox">
			<material>Gazebo/Grey</material>
		</gazebo>

		<!-- index med -->
		<joint name="${prefix}index_med" type="fixed">
			<origin xyz="-0.00285 -0.04341 0" rpy="0 0 0"/>
			<parent link="${prefix}index_prox"/>
			<child link="${prefix}index_med"/>
		</joint>

		<link name="${prefix}index_med">
			<collision>
				<origin xyz="0 0 0" rpy="0 0 0"/>
				<geometry>
					<mesh filename="package://hdt_7dof_description/meshes/hdt_7dof_index_med_right.STL"/>
				</geometry>
			</collision>

			<visual>
				<origin xyz="0 0 0" rpy="0 0 0"/>
				<geometry>
					<mesh filename="package://hdt_7dof_description/meshes/hdt_7dof_index_med_right.STL"/>
				</geometry>
				<material name="${prefix}black"/>
			</visual>

			<inertial>
				<origin xyz="0.00353 -0.01162 0" rpy="0 0 0"/>
				<mass value="0.0085"/>
				<inertia
				ixx="0.000001639" ixy="0.000000096" ixz="0.0"
				iyy="0.000000981" iyz="0.0"
				izz="0.000001099"/>
			</inertial>
		</link>
		<gazebo reference="${prefix}index_med">
			<material>Gazebo/Black</material>
		</gazebo>

		<!-- index dist -->
		<joint name="${prefix}index_dist" type="fixed">
			<origin xyz="0.0009 -0.02769 0" rpy="0 0 0"/>
			<parent link="${prefix}index_med"/>
			<child link="${prefix}index_dist"/>
		</joint>

		<link name="${prefix}index_dist">
			<collision>
				<origin xyz="0 0 0" rpy="0 0 0"/>
				<geometry>
					<mesh filename="package://hdt_7dof_description/meshes/hdt_7dof_index_dist_right.STL"/>
				</geometry>
			</collision>

			<visual>
				<origin xyz="0 0 0" rpy="0 0 0"/>
				<geometry>
					<mesh filename="package://hdt_7dof_description/meshes/hdt_7dof_index_dist_right.STL"/>
				</geometry>
				<material name="${prefix}grey"/>
			</visual>

			<inertial>
				<origin xyz="0.00131 -0.01323 0" rpy="0 0 0"/>
				<mass value="0.0092"/>
				<inertia
				ixx="0.000000837" ixy="0.0" ixz="0.0"
				iyy="0.000000695" iyz="0.0"
				izz="0.00000066"/>
			</inertial>
		</link>
		<gazebo reference="${prefix}index_dist">
			<material>Gazebo/Grey</material>
		</gazebo>

		<!-- ring prox -->
		<joint name="${prefix}ring_prox" type="revolute">
			<hdt id="13" kmin="5" kmax="20" inertia="0.01"/>
			<axis xyz="0 0 1"/>
			<limit effort="4.0" lower="-0.7854" upper="1.5708" velocity="4.1888"/>
			<origin xyz="0 -0.16325 -0.02701" rpy="0 0 0"/>
			<parent link="${prefix}palm"/>
			<child link="${prefix}ring_prox"/>
			<dynamics damping="0.7" friction="0.0"/>
		</joint>

		<transmission name="${prefix}tran13">
			<type>transmission_interface/SimpleTransmission</type>
			<joint name="${prefix}ring_prox">
				<hardwareInterface>EffortJointInterface</hardwareInterface>
			</joint>
			<actuator name="${prefix}motor13">
				<mechanicalReduction>1</mechanicalReduction>
			</actuator>
		</transmission>

		<link name="${prefix}ring_prox">
			<collision>
				<origin xyz="0 0 0" rpy="0 0 0"/>
				<geometry>
					<mesh filename="package://hdt_7dof_description/meshes/hdt_7dof_ring_prox_right.STL"/>
				</geometry>
			</collision>

			<visual>
				<origin xyz="0 0 0" rpy="0 0 0"/>
				<geometry>
					<mesh filename="package://hdt_7dof_description/meshes/hdt_7dof_ring_prox_right.STL"/>
				</geometry>
				<material name="${prefix}grey"/>
			</visual>

			<inertial>
				<origin xyz="-0.001 -0.02063 0" rpy="0 0 0"/>
				<mass value="0.02523"/>
				<xacro:default_inertia />
				<!-- <inertia
				ixx="0.000005374" ixy="-0.000000071" ixz="0.0"
				iyy="0.000002921" iyz="0.0"
				izz="0.000004718"/> -->
			</inertial>
		</link>
		<gazebo reference="${prefix}ring_prox">
			<material>Gazebo/Grey</material>
		</gazebo>

		<!-- ring med -->
		<joint name="${prefix}ring_med" type="fixed">
			<origin xyz="-0.00285 -0.04341 0" rpy="0 0 0"/>
			<parent link="${prefix}ring_prox"/>
			<child link="${prefix}ring_med"/>
		</joint>

		<link name="${prefix}ring_med">
			<collision>
				<origin xyz="0 0 0" rpy="0 0 0"/>
				<geometry>
					<mesh filename="package://hdt_7dof_description/meshes/hdt_7dof_ring_med_right.STL"/>
				</geometry>
			</collision>

			<visual>
				<origin xyz="0 0 0" rpy="0 0 0"/>
				<geometry>
					<mesh filename="package://hdt_7dof_description/meshes/hdt_7dof_ring_med_right.STL"/>
				</geometry>
				<material name="${prefix}black"/>
			</visual>

			<inertial>
				<origin xyz="0.00353 -0.01162 0" rpy="0 0 0"/>
				<mass value="0.0085"/>
				<inertia
				ixx="0.000001639" ixy="0.000000096" ixz="0.0"
				iyy="0.000000981" iyz="0.0"
				izz="0.000001099"/>
			</inertial>
		</link>
		<gazebo reference="${prefix}ring_med">
			<material>Gazebo/Black</material>
		</gazebo>

		<!-- ring dist -->
		<joint name="${prefix}ring_dist" type="fixed">
			<origin xyz="0.0009 -0.02769 0" rpy="0 0 0"/>
			<parent link="${prefix}ring_med"/>
			<child link="${prefix}ring_dist"/>
		</joint>

		<link name="${prefix}ring_dist">
			<collision>
				<origin xyz="0 0 0" rpy="0 0 0"/>
				<geometry>
					<mesh filename="package://hdt_7dof_description/meshes/hdt_7dof_ring_dist_right.STL"/>
				</geometry>
			</collision>

			<visual>
				<origin xyz="0 0 0" rpy="0 0 0"/>
				<geometry>
					<mesh filename="package://hdt_7dof_description/meshes/hdt_7dof_ring_dist_right.STL"/>
				</geometry>
				<material name="${prefix}grey"/>
			</visual>

			<inertial>
				<origin xyz="0.00131 -0.01323 0" rpy="0 0 0"/>
				<mass value="0.0092"/>
				<inertia
				ixx="0.000000837" ixy="0.0" ixz="0.0"
				iyy="0.000000695" iyz="0.0"
				izz="0.00000066"/>
			</inertial>
		</link>
		<gazebo reference="${prefix}ring_dist">
			<material>Gazebo/Grey</material>
		</gazebo>
	</xacro:macro>
</robot>

